import { render, screen, fireEvent } from '@testing-library/react';
import ErrorBoundary from './ErrorBoundary';

const ThrowError = () => {
  throw new Error('Test error');
};

describe('ErrorBoundary', () => {
  beforeEach(() => {
    jest.spyOn(console, 'error').mockImplementation(() => {});
  });

  afterEach(() => {
    jest.restoreAllMocks();
  });

  it('renders children when there is no error', () => {
    render(
      <ErrorBoundary>
        <div>Test content</div>
      </ErrorBoundary>
    );

    expect(screen.getByText('Test content')).toBeInTheDocument();
  });

  it('renders error UI when there is an error', () => {
    render(
      <ErrorBoundary>
        <ThrowError />
      </ErrorBoundary>
    );

    expect(screen.getByText('Oops!')).toBeInTheDocument();
    expect(screen.getByText('Something went wrong')).toBeInTheDocument();
    expect(screen.getByText('Try Again')).toBeInTheDocument();
  });

  it('renders custom fallback when provided and there is an error', () => {
    const fallback = <div>Custom error message</div>;
    
    render(
      <ErrorBoundary fallback={fallback}>
        <ThrowError />
      </ErrorBoundary>
    );

    expect(screen.getByText('Custom error message')).toBeInTheDocument();
  });

  it('reloads the page when try again button is clicked', () => {
    const reloadMock = jest.fn();
    Object.defineProperty(window, 'location', {
      value: { reload: reloadMock },
      writable: true
    });

    render(
      <ErrorBoundary>
        <ThrowError />
      </ErrorBoundary>
    );

    fireEvent.click(screen.getByText('Try Again'));
    expect(reloadMock).toHaveBeenCalled();
  });
});